Workbook

Sheet data
A1: CRIM | B1: ZN | C1: INDUS | D1: CHAS | E1: NOX | F1: RM | G1: AGE | H1: DIS | I1: RAD | J1: TAX | K1: PTRATIO | L1: B | M1: LSTAT | N1: MEDV | R1: MEDV | S1: PTRATIO | T1: TAX | U1: MEDV_BIN | V1: MEDV LOW | W1: MEDV AVERAGE | X1: MEDV HIGH | Y1: MEDV VERY LOW | Z1: MEDV VERY HIGH | AV1: RM | AW1: LSTAT | AX1: MEDV | AY1: LSTAT-Bin | AZ1: LSTAT BIN 0-4 | BA1: LSTAT BIN 5-9 | BB1: LSTAT BIN 10-14 | BC1: LSTAT BIN 15-19 | BD1: LSTAT BIN 20-24 | BE1: LSTAT BIN 25-29 | BF1: LSTAT BIN 30-34 | BG1: LSTAT BIN 35-39 | BH1: LSTAT BIN 40-44 | BJ1: ="MEDV CORR " &A1 -> MEDV CORR CRIM | BK1: ="MEDV CORR " &B1 -> MEDV CORR ZN | BL1: ="MEDV CORR " &C1 -> MEDV CORR INDUS | BM1: ="MEDV CORR " &D1 -> MEDV CORR CHAS | BN1: ="MEDV CORR " &E1 -> MEDV CORR NOX | BO1: ="MEDV CORR " &F1 -> MEDV CORR RM | BP1: ="MEDV CORR " &G1 -> MEDV CORR AGE | BQ1: ="MEDV CORR " &H1 -> MEDV CORR DIS | ... BV1: ="MEDV CORR " &M1 -> MEDV CORR LSTAT
A2: 8.98296 | B2: 0 | C2: 18.1 | D2: 1 | E2: 0.77 | F2: 6.212 | G2: 97.4 | H2: 2.1222 | I2: 24 | J2: 666 | K2: 20.2 | L2: 377.73 | M2: 17.6 | N2: 17.8 | R2: 17.8 | S2: 20.2 | T2: 666 | U2: LOW | V2: 666 | AV2: 7.2 | AW2: 4 | AX2: 35 | AY2: 0-4 | AZ2: 35 | BJ2: =CORREL(boston[[MEDV]:[MEDV]],boston[CRIM]) -> -0.38830461 | BK2: =CORREL(boston[[MEDV]:[MEDV]],boston[ZN]) -> 0.36044534 | BL2: =CORREL(boston[[MEDV]:[MEDV]],boston[INDUS]) -> -0.48372516 | BM2: =CORREL(boston[[MEDV]:[MEDV]],boston[CHAS]) -> 0.17526018 | BN2: =CORREL(boston[[MEDV]:[MEDV]],boston[NOX]) -> -0.42732077 | BO2: =CORREL(boston[[MEDV]:[MEDV]],boston[RM]) -> 0.69535995 | BP2: =CORREL(boston[[MEDV]:[MEDV]],boston[AGE]) -> -0.37695457 | BQ2: =CORREL(boston[[MEDV]:[MEDV]],boston[DIS]) -> 0.24992873 | BR2: =CORREL(boston[[MEDV]:[MEDV]],boston[RAD]) -> -0.38162623 | BS2: =CORREL(boston[[MEDV]:[MEDV]],boston[TAX]) -> -0.46853593 | BT2: =CORREL(boston[[MEDV]:[MEDV]],boston[PTRATIO]) -> -0.50778669 | BU2: =CORREL(boston[[MEDV]:[MEDV]],boston[B]) -> 0.33346082 | BV2: =CORREL(boston[[MEDV]:[MEDV]],boston[LSTAT]) -> -0.73766273
A3: 3.8497 | B3: 0 | C3: 18.1 | D3: 1 | E3: 0.77 | F3: 6.395 | G3: 91 | H3: 2.5052 | I3: 24 | J3: 666 | K3: 20.2 | L3: 391.34 | M3: 13.27 | N3: 21.7 | R3: 19.9 | S3: 20.2 | T3: 666 | U3: LOW | V3: 666 | AV3: 7 | AW3: 3 | AX3: 33 | AY3: 0-4 | AZ3: 33 | BI3: ABS() | BJ3: =ABS(BJ2) -> 0.38830461 | BK3: =ABS(BK2) -> 0.36044534 | BL3: =ABS(BL2) -> 0.48372516 | BM3: =ABS(BM2) -> 0.17526018 | BN3: =ABS(BN2) -> 0.42732077 | BO3: =ABS(BO2) -> 0.69535995 | BP3: =ABS(BP2) -> 0.37695457 | BQ3: =ABS(BQ2) -> 0.24992873 | ... BV3: =ABS(BV2) -> 0.73766273
A4: 5.20177 | B4: 0 | C4: 18.1 | D4: 1 | E4: 0.77 | F4: 6.127 | G4: 83.4 | H4: 2.7227 | I4: 24 | J4: 666 | K4: 20.2 | L4: 395.43 | M4: 11.48 | N4: 22.7 | R4: 16.8 | S4: 20.2 | T4: 666 | U4: LOW | V4: 666 | AV4: 6.6 | AW4: 4 | AX4: 31 | AY4: 0-4 | AZ4: 31 | BJ4: =BJ3>0.65 -> FALSE | BK4: =BK3>0.65 -> FALSE | BL4: =BL3>0.65 -> FALSE | BM4: =BM3>0.65 -> FALSE | BN4: =BN3>0.65 -> FALSE | BO4: =BO3>0.65 -> TRUE | BP4: =BP3>0.65 -> FALSE | BQ4: =BQ3>0.65 -> FALSE | ... BV4: =BV3>0.65 -> TRUE
A5: 4.26131 | B5: 0 | C5: 18.1 | D5: 0 | E5: 0.77 | F5: 6.112 | G5: 81.3 | H5: 2.5091 | I5: 24 | J5: 666 | K5: 20.2 | L5: 390.74 | M5: 12.67 | N5: 22.6 | R5: 13.8 | S5: 20.2 | T5: 666 | U5: LOW | V5: 666 | AV5: 7 | AW5: 2 | AX5: 35 | AY5: 0-4 | AZ5: 35 | BJ5: ="CORR " & TEXT(BJ2,"0,000") -> CORR -0,388 | BK5: ="CORR " & TEXT(BK2,"0,000") -> CORR 0,360 | BL5: ="CORR " & TEXT(BL2,"0,000") -> CORR -0,484 | BM5: ="CORR " & TEXT(BM2,"0,000") -> CORR 0,175 | BN5: ="CORR " & TEXT(BN2,"0,000") -> CORR -0,427 | BO5: ="CORR " & TEXT(BO2,"0,000") -> CORR 0,695 | BP5: ="CORR " & TEXT(BP2,"0,000") -> CORR -0,377 | BQ5: ="CORR " & TEXT(BQ2,"0,000") -> CORR 0,250 | ... BV5: ="CORR " & TEXT(BV2,"0,000") -> CORR -0,738
A6: 4.54192 | B6: 0 | C6: 18.1 | D6: 0 | E6: 0.77 | F6: 6.398 | G6: 88 | H6: 2.5182 | I6: 24 | J6: 666 | K6: 20.2 | L6: 374.56 | M6: 7.79 | N6: 25 | R6: 13.8 | S6: 20.2 | T6: 666 | U6: LOW | V6: 666 | AV6: 6.8 | AW6: 4 | AX6: 32 | AY6: 0-4 | AZ6: 32
A7: 3.83684 | B7: 0 | C7: 18.1 | D7: 0 | E7: 0.77 | F7: 6.251 | G7: 91.1 | H7: 2.2955 | I7: 24 | J7: 666 | K7: 20.2 | L7: 350.65 | M7: 14.19 | N7: 19.9 | R7: 15 | S7: 20.2 | T7: 666 | U7: LOW | V7: 666 | AV7: 8.1 | AW7: 4 | AX7: 39 | AY7: 0-4 | AZ7: 39
A8: 3.67822 | B8: 0 | C8: 18.1 | D8: 0 | E8: 0.77 | F8: 5.362 | G8: 96.2 | H8: 2.1036 | I8: 24 | J8: 666 | K8: 20.2 | L8: 380.79 | M8: 10.19 | N8: 20.8 | R8: 13.9 | S8: 20.2 | T8: 666 | U8: LOW | V8: 666 | AV8: 7.8 | AW8: 4 | AX8: 44 | AY8: 0-4 | AZ8: 44
A9: 4.22239 | B9: 0 | C9: 18.1 | D9: 1 | E9: 0.77 | F9: 5.803 | G9: 89 | H9: 1.9047 | I9: 24 | J9: 666 | K9: 20.2 | L9: 353.04 | M9: 14.64 | N9: 16.8 | R9: 13.3 | S9: 20.2 | T9: 666 | U9: LOW | V9: 666 | AV9: 7.5 | AW9: 2 | AX9: 50 | AY9: 0-4 | AZ9: 50
A10: 3.47428 | B10: 0 | C10: 18.1 | D10: 1 | E10: 0.718 | F10: 8.78 | G10: 82.9 | H10: 1.9047 | I10: 24 | J10: 666 | K10: 20.2 | L10: 354.55 | M10: 5.29 | N10: 21.9 | R10: 13.1 | S10: 20.2 | T10: 666 | U10: LOW | V10: 666 | AV10: 7.8 | AW10: 2 | AX10: 50 | AY10: 0-4 | AZ10: 50
A11: 4.55587 | B11: 0 | C11: 18.1 | D11: 0 | E11: 0.718 | F11: 3.561 | G11: 87.9 | H11: 1.6132 | I11: 24 | J11: 666 | K11: 20.2 | L11: 354.7 | M11: 7.12 | N11: 27.5 | R11: 10.2 | S11: 20.2 | T11: 666 | U11: LOW | V11: 666 | AV11: 8.4 | AW11: 3 | AX11: 50 | AY11: 0-4 | AZ11: 50
A12: 3.69695 | B12: 0 | C12: 18.1 | D12: 0 | E12: 0.718 | F12: 4.963 | G12: 91.4 | H12: 1.7523 | I12: 24 | J12: 666 | K12: 20.2 | L12: 316.03 | M12: 14 | N12: 21.9 | R12: 10.4 | S12: 20.2 | T12: 666 | U12: LOW | V12: 666 | AV12: 7.9 | AW12: 4 | AX12: 50 | AY12: 0-4 | AZ12: 50
A13: 13.5222 | B13: 0 | C13: 18.1 | D13: 0 | E13: 0.631 | F13: 3.863 | G13: 100 | H13: 1.5106 | I13: 24 | J13: 666 | K13: 20.2 | L13: 131.42 | M13: 13.33 | N13: 23.1 | R13: 10.9 | S13: 20.2 | T13: 666 | U13: LOW | V13: 666 | AV13: 7.8 | AW13: 4 | AX13: 50 | AY13: 0-4 | AZ13: 50
A14: 4.89822 | B14: 0 | C14: 18.1 | D14: 0 | E14: 0.631 | F14: 4.97 | G14: 100 | H14: 1.3325 | I14: 24 | J14: 666 | K14: 20.2 | L14: 375.52 | M14: 3.26 | N14: 50 | R14: 11.3 | S14: 20.2 | T14: 666 | U14: LOW | V14: 666 | AV14: 7.2 | AW14: 3 | AX14: 36 | AY14: 0-4 | AZ14: 36
A15: 5.66998 | B15: 0 | C15: 18.1 | D15: 1 | E15: 0.631 | F15: 6.683 | G15: 96.8 | H15: 1.3567 | I15: 24 | J15: 666 | K15: 20.2 | L15: 375.33 | M15: 3.73 | N15: 50 | R15: 12.3 | S15: 20.2 | T15: 666 | U15: LOW | V15: 666 | AV15: 6.6 | AW15: 4 | AX15: 29 | AY15: 0-4 | AZ15: 29
A16: 6.53876 | B16: 0 | C16: 18.1 | D16: 1 | E16: 0.631 | F16: 7.016 | G16: 97.5 | H16: 1.2024 | I16: 24 | J16: 666 | K16: 20.2 | L16: 392.05 | M16: 2.96 | N16: 50 | R16: 8.8 | S16: 20.2 | T16: 666 | U16: LOW | V16: 666 | AV16: 7.9 | AW16: 3 | AX16: 50 | AY16: 0-4 | AZ16: 50
A17: 9.2323 | B17: 0 | C17: 18.1 | D17: 0 | E17: 0.631 | F17: 6.216 | G17: 100 | H17: 1.1691 | I17: 24 | J17: 666 | K17: 20.2 | L17: 366.15 | M17: 9.53 | N17: 50 | R17: 10.5 | S17: 20.2 | T17: 666 | U17: LOW | V17: 666 | AV17: 7.3 | AW17: 4 | AX17: 33 | AY17: 0-4 | AZ17: 33
... A44: 38.3518 | B44: 0 | C44: 18.1 | D44: 0 | E44: 0.693 | F44: 5.453 | G44: 100 | H44: 1.4896 | I44: 24 | J44: 666 | K44: 20.2 | L44: 396.9 | M44: 30.59 | N44: 5 | R44: 10.2 | S44: 20.2 | T44: 666 | U44: LOW | V44: 666 | AV44: 7 | AW44: 3 | AX44: 50 | AY44: 0-4 | AZ44: 50
A45: 9.91655 | B45: 0 | C45: 18.1 | D45: 0 | E45: 0.693 | F45: 5.852 | G45: 77.8 | H45: 1.5004 | I45: 24 | J45: 666 | K45: 20.2 | L45: 338.16 | M45: 29.97 | N45: 6.3 | R45: 10.9 | S45: 20.2 | T45: 666 | U45: LOW | V45: 666 | AV45: 6 | AW45: 12 | AX45: 23 | AY45: 10-14 | BB45: 23
A46: 25.0461 | B46: 0 | C46: 18.1 | D46: 0 | E46: 0.693 | F46: 5.987 | G46: 100 | H46: 1.5888 | I46: 24 | J46: 666 | K46: 20.2 | L46: 396.9 | M46: 26.77 | N46: 5.6 | R46: 11 | S46: 20.2 | T46: 666 | U46: LOW | V46: 666 | AV46: 6 | AW46: 13 | AX46: 19 | AY46: 10-14 | BB46: 19
A47: 14.2362 | B47: 0 | C47: 18.1 | D47: 0 | E47: 0.693 | F47: 6.343 | G47: 100 | H47: 1.5741 | I47: 24 | J47: 666 | K47: 20.2 | L47: 396.9 | M47: 20.32 | N47: 7.2 | R47: 9.5 | S47: 20.2 | T47: 666 | U47: LOW | V47: 666 | AV47: 6.1 | AW47: 10 | AX47: 18 | AY47: 10-14 | BB47: 18
A48: 9.59571 | B48: 0 | C48: 18.1 | D48: 0 | E48: 0.693 | F48: 6.404 | G48: 100 | H48: 1.639 | I48: 24 | J48: 666 | K48: 20.2 | L48: 376.11 | M48: 20.31 | N48: 12.1 | R48: 14.5 | S48: 20.2 | T48: 666 | U48: LOW | V48: 666 | AV48: 5.5 | AW48: 12 | AX48: 20 | AY48: 10-14 | BB48: 20
A49: 24.8017 | B49: 0 | C49: 18.1 | D49: 0 | E49: 0.693 | F49: 5.349 | G49: 96 | H49: 1.7028 | I49: 24 | J49: 666 | K49: 20.2 | L49: 396.9 | M49: 19.77 | N49: 8.3 | R49: 14.1 | S49: 20.2 | T49: 666 | U49: LOW | V49: 666 | AV49: 5.7 | AW49: 11 | AX49: 18 | AY49: 10-14 | BB49: 18
A50: 41.5292 | B50: 0 | C50: 18.1 | D50: 0 | E50: 0.693 | F50: 5.531 | G50: 85.4 | H50: 1.6074 | I50: 24 | J50: 666 | K50: 20.2 | L50: 329.46 | M50: 27.38 | N50: 8.5 | R50: 16.1 | S50: 20.2 | T50: 666 | U50: LOW | V50: 666 | AV50: 6 | AW50: 14 | AX50: 20 | AY50: 10-14 | BB50: 20
A51: 67.9208 | B51: 0 | C51: 18.1 | D51: 0 | E51: 0.693 | F51: 5.683 | G51: 100 | H51: 1.4254 | I51: 24 | J51: 666 | K51: 20.2 | L51: 384.97 | M51: 22.98 | N51: 5 | R51: 14.3 | S51: 20.2 | T51: 666 | U51: LOW | V51: 666 | AV51: 6.5 | AW51: 13 | AX51: 18 | AY51: 10-14 | BB51: 18
A52: 20.7162 | B52: 0 | C52: 18.1 | D52: 0 | E52: 0.659 | F52: 4.138 | G52: 100 | H52: 1.1781 | I52: 24 | J52: 666 | K52: 20.2 | L52: 370.22 | M52: 23.34 | N52: 11.9 | R52: 11.7 | S52: 20.2 | T52: 666 | U52: LOW | V52: 666 | AV52: 6.7 | AW52: 12 | AX52: 21 | AY52: 10-14 | BB52: 21
A53: 11.9511 | B53: 0 | C53: 18.1 | D53: 0 | E53: 0.659 | F53: 5.608 | G53: 100 | H53: 1.2852 | I53: 24 | J53: 666 | K53: 20.2 | L53: 332.09 | M53: 12.13 | N53: 27.9 | R53: 13.4 | S53: 20.2 | T53: 666 | U53: LOW | V53: 666 | AV53: 6.1 | AW53: 13 | AX53: 14 | AY53: 10-14 | BB53: 14
A54: 7.40389 | B54: 0 | C54: 18.1 | D54: 0 | E54: 0.597 | F54: 5.617 | G54: 97.9 | H54: 1.4547 | I54: 24 | J54: 666 | K54: 20.2 | L54: 314.64 | M54: 26.4 | N54: 17.2 | R54: 9.6 | S54: 20.2 | T54: 666 | U54: LOW | V54: 666 | AV54: 5.9 | AW54: 10 | AX54: 19 | AY54: 10-14 | BB54: 19
A55: 14.4383 | B55: 0 | C55: 18.1 | D55: 0 | E55: 0.597 | F55: 6.852 | G55: 100 | H55: 1.4655 | I55: 24 | J55: 666 | K55: 20.2 | L55: 179.36 | M55: 19.78 | N55: 27.5 | R55: 8.7 | S55: 20.2 | T55: 666 | U55: LOW | V55: 666 | AV55: 5.8 | AW55: 11 | AX55: 20 | AY55: 10-14 | BB55: 20
A56: 51.1358 | B56: 0 | C56: 18.1 | D56: 0 | E56: 0.597 | F56: 5.757 | G56: 100 | H56: 1.413 | I56: 24 | J56: 666 | K56: 20.2 | L56: 2.6 | M56: 10.11 | N56: 15 | R56: 8.4 | S56: 20.2 | T56: 666 | U56: LOW | V56: 666 | AV56: 6 | AW56: 10 | AX56: 25 | AY56: 10-14 | BB56: 25
... A91: 10.6718 | B91: 0 | C91: 18.1 | D91: 0 | E91: 0.74 | F91: 6.459 | G91: 94.8 | H91: 1.9879 | I91: 24 | J91: 666 | K91: 20.2 | L91: 43.06 | M91: 23.98 | N91: 11.8 | R91: 19.1 | S91: 20.2 | T91: 666 | U91: LOW | V91: 666 | AV91: 5.4 | AW91: 13 | AX91: 20 | AY91: 10-14 | BB91: 20
A92: 6.28807 | B92: 0 | C92: 18.1 | D92: 0 | E92: 0.74 | F92: 6.341 | G92: 96.4 | H92: 2.072 | I92: 24 | J92: 666 | K92: 20.2 | L92: 318.01 | M92: 17.79 | N92: 14.9 | R92: 21.7 | S92: 20.2 | T92: 666 | U92: AVERAGE | W92: 666 | AV92: 5 | AW92: 12 | AX92: 15 | AY92: 10-14 | BB92: 15
A93: 9.92485 | B93: 0 | C93: 18.1 | D93: 0 | E93: 0.74 | F93: 6.251 | G93: 96.6 | H93: 2.198 | I93: 24 | J93: 666 | K93: 20.2 | L93: 388.52 | M93: 16.44 | N93: 12.6 | R93: 22.7 | S93: 20.2 | T93: 666 | U93: AVERAGE | W93: 666 | AV93: 5.9 | AW93: 12 | AX93: 23 | AY93: 10-14 | BB93: 23
A94: 9.32909 | B94: 0 | C94: 18.1 | D94: 0 | E94: 0.713 | F94: 6.185 | G94: 98.7 | H94: 2.2616 | I94: 24 | J94: 666 | K94: 20.2 | L94: 396.9 | M94: 18.13 | N94: 14.1 | R94: 22.6 | S94: 20.2 | T94: 666 | U94: AVERAGE | W94: 666 | AV94: 6.1 | AW94: 10 | AX94: 25 | AY94: 10-14 | BB94: 25
A95: 7.52601 | B95: 0 | C95: 18.1 | D95: 0 | E95: 0.713 | F95: 6.417 | G95: 98.3 | H95: 2.185 | I95: 24 | J95: 666 | K95: 20.2 | L95: 304.21 | M95: 19.31 | N95: 13 | R95: 25 | S95: 20.2 | T95: 666 | U95: AVERAGE | W95: 666 | AV95: 5.9 | AW95: 12 | AX95: 24 | AY95: 10-14 | BB95: 24
A96: 6.71772 | B96: 0 | C96: 18.1 | D96: 0 | E96: 0.713 | F96: 6.749 | G96: 92.6 | H96: 2.3236 | I96: 24 | J96: 666 | K96: 20.2 | L96: 0.32 | M96: 17.44 | N96: 13.4 | R96: 20.8 | S96: 20.2 | T96: 666 | U96: AVERAGE | W96: 666 | AV96: 6.3 | AW96: 11 | AX96: 24 | AY96: 10-14 | BB96: 24
A97: 5.44114 | B97: 0 | C97: 18.1 | D97: 0 | E97: 0.713 | F97: 6.655 | G97: 98.2 | H97: 2.3552 | I97: 24 | J97: 666 | K97: 20.2 | L97: 355.29 | M97: 17.73 | N97: 15.2 | R97: 21.9 | S97: 20.2 | T97: 666 | U97: AVERAGE | W97: 666 | AV97: 6.4 | AW97: 11 | AX97: 22 | AY97: 10-14 | BB97: 22
A98: 5.09017 | B98: 0 | C98: 18.1 | D98: 0 | E98: 0.713 | F98: 6.297 | G98: 91.8 | H98: 2.3682 | I98: 24 | J98: 666 | K98: 20.2 | L98: 385.09 | M98: 17.27 | N98: 16.1 | R98: 27.5 | S98: 20.2 | T98: 666 | U98: AVERAGE | W98: 666 | AV98: 5.9 | AW98: 14 | AX98: 17 | AY98: 10-14 | BB98: 17
A99: 8.24809 | B99: 0 | C99: 18.1 | D99: 0 | E99: 0.713 | F99: 7.393 | G99: 99.3 | H99: 2.4527 | I99: 24 | J99: 666 | K99: 20.2 | L99: 375.87 | M99: 16.74 | N99: 17.8 | R99: 21.9 | S99: 20.2 | T99: 666 | U99: AVERAGE | W99: 666 | AV99: 5.9 | AW99: 12 | AX99: 19 | AY99: 10-14 | BB99: 19
A100: 9.51363 | B100: 0 | C100: 18.1 | D100: 0 | E100: 0.713 | F100: 6.728 | G100: 94.1 | H100: 2.4961 | I100: 24 | J100: 666 | K100: 20.2 | L100: 6.68 | M100: 18.71 | N100: 14.9 | R100: 23.1 | S100: 20.2 | T100: 666 | U100: AVERAGE | W100: 666 | AV100: 5.9 | AW100: 10 | AX100: 23 | AY100: 10-14 | BB100: 23
...

Sheet dashboard
L18: s

Sheet Q5
A1: SUMMARY OUTPUT Q5
A3: Regression Statistics
A4: Multiple R | B4: 0.84344548
A5: R Square | B5: 0.71140028
A6: Adjusted R Square | B6: 0.70793014
A7: Standard Error | B7: 4.9704358
A8: Observations | B8: 506
A10: ANOVA
B11: df | C11: SS | D11: MS | E11: F | F11: Significance F
A12: Regression | B12: 6 | C12: 30388.385 | D12: 5064.7308 | E12: 205.0064 | F12: 3.530034e-131
A13: Residual | B13: 499 | C13: 12327.911 | D13: 24.705232
A14: Total | B14: 505 | C14: 42716.295
B16: Coefficients | C16: Standard Error | D16: t Stat | E16: P-value | F16: Lower 95% | G16: Upper 95% | H16: Lower 95,0% | I16: Upper 95,0%
A17: Intercept | B17: 35.54553 | C17: 4.6633484 | D17: 7.6223193 | E17: 1.2653526e-13 | F17: 26.383313 | G17: 44.707748 | H17: 26.383313 | I17: 44.707748
A18: CRIM | B18: -0.072023627 | C18: 0.030101886 | D18: -2.3926616 | E18: 0.01709549 | F18: -0.13116569 | G18: -0.012881568 | H18: -0.13116569 | I18: -0.012881568
A19: RM | B19: 4.2519613 | C19: 0.41176523 | D19: 10.326179 | E19: 8.7341515e-23 | F19: 3.4429541 | G19: 5.0609685 | H19: 3.4429541 | I19: 5.0609685
A20: PTRATIO | B20: -1.0008035 | C20: 0.11453847 | D20: -8.7377061 | E20: 3.624427e-17 | F20: -1.2258406 | G20: -0.77576637 | H20: -1.2258406 | I20: -0.77576637
A21: LSTAT | B21: -0.55353166 | C21: 0.049082898 | D21: -11.277485 | E21: 1.9716057e-26 | F21: -0.64996628 | G21: -0.45709705 | H21: -0.64996628 | I21: -0.45709705
A22: NOX | B22: -17.006654 | C22: 3.2719171 | D22: -5.1977644 | E22: 2.9464031e-07 | F22: -23.435086 | G22: -10.578223 | H22: -23.435086 | I22: -10.578223
A23: DIS | B23: -1.2033453 | C23: 0.16781568 | D23: -7.1706369 | E23: 2.7082481e-12 | F23: -1.5330577 | G23: -0.87363293 | H23: -1.5330577 | I23: -0.87363293
Q509: Column1
